[2020-12-04 22:39:26] _internal.py[line:113] INFO 11262  * Running on http://127.0.0.1:5000/ (Press CTRL+C to quit)
[2020-12-04 22:39:27] CaffeOpencvApp.py[line:91] INFO 11460 infer process start succeed
[2020-12-04 22:39:43] MyServer.py[line:34] INFO 11262 get data message, the data keys: dict_keys(['input', 'uuid', 'loadmodel', 'image_1'])
[2020-12-04 22:39:43] CaffeOpencvApp.py[line:95] INFO 11460 load modelfile: ('modelweight/MobileNetSSD_deploy.prototxt', 'modelweight/MobileNetSSD_deploy.caffemodel')
[2020-12-04 22:39:43] CaffeOpencvApp.py[line:101] INFO 11460 model has load('modelweight/MobileNetSSD_deploy.prototxt', 'modelweight/MobileNetSSD_deploy.caffemodel')
[2020-12-04 22:39:44] MyServer.py[line:39] INFO 11262 model online success
[2020-12-04 22:39:44] _internal.py[line:113] INFO 11262 127.0.0.1 - - [04/Dec/2020 22:39:44] "[37mPOST /online HTTP/1.1[0m" 200 -
[2020-12-04 22:39:50] MyServer.py[line:62] INFO 11262 get data: uuid: dadasdsadas;input: image:1 
[2020-12-04 22:40:33] app.py[line:1892] ERROR 11262 Exception on /postdata [POST]
Traceback (most recent call last):
  File "/root/anaconda3/envs/py3/lib/python3.6/site-packages/flask/app.py", line 2447, in wsgi_app
    response = self.full_dispatch_request()
  File "/root/anaconda3/envs/py3/lib/python3.6/site-packages/flask/app.py", line 1952, in full_dispatch_request
    rv = self.handle_user_exception(e)
  File "/root/anaconda3/envs/py3/lib/python3.6/site-packages/flask/app.py", line 1821, in handle_user_exception
    reraise(exc_type, exc_value, tb)
  File "/root/anaconda3/envs/py3/lib/python3.6/site-packages/flask/_compat.py", line 39, in reraise
    raise value
  File "/root/anaconda3/envs/py3/lib/python3.6/site-packages/flask/app.py", line 1950, in full_dispatch_request
    rv = self.dispatch_request()
  File "/root/anaconda3/envs/py3/lib/python3.6/site-packages/flask/app.py", line 1936, in dispatch_request
    return self.view_functions[rule.endpoint](**req.view_args)
  File "/root/MyApp/MyServer.py", line 79, in postdata
    processdata=APPqueuedict.recvdata(uuid)
  File "/root/MyApp/MessageQueue.py", line 134, in recvdata
    returndata= self.queuedict[uuid].get()
  File "<string>", line 2, in get
  File "/root/anaconda3/envs/py3/lib/python3.6/multiprocessing/managers.py", line 757, in _callmethod
    kind, result = conn.recv()
  File "/root/anaconda3/envs/py3/lib/python3.6/multiprocessing/connection.py", line 250, in recv
    buf = self._recv_bytes()
  File "/root/anaconda3/envs/py3/lib/python3.6/multiprocessing/connection.py", line 407, in _recv_bytes
    buf = self._recv(4)
  File "/root/anaconda3/envs/py3/lib/python3.6/multiprocessing/connection.py", line 383, in _recv
    raise EOFError
EOFError
[2020-12-04 22:40:33] _internal.py[line:113] INFO 11262 127.0.0.1 - - [04/Dec/2020 22:40:33] "[35m[1mPOST /postdata HTTP/1.1[0m" 500 -
[2020-12-04 22:41:19] _internal.py[line:113] INFO 11787  * Running on http://127.0.0.1:5000/ (Press CTRL+C to quit)
[2020-12-04 22:41:20] CaffeOpencvApp.py[line:91] INFO 11991 infer process start succeed
[2020-12-04 22:41:31] MyServer.py[line:34] INFO 11787 get data message, the data keys: dict_keys(['input', 'uuid', 'loadmodel', 'image_1'])
[2020-12-04 22:41:31] CaffeOpencvApp.py[line:95] INFO 11991 load modelfile: ('modelweight/MobileNetSSD_deploy.prototxt', 'modelweight/MobileNetSSD_deploy.caffemodel')
[2020-12-04 22:41:31] CaffeOpencvApp.py[line:101] INFO 11991 model has load('modelweight/MobileNetSSD_deploy.prototxt', 'modelweight/MobileNetSSD_deploy.caffemodel')
[2020-12-04 22:41:32] MyServer.py[line:39] INFO 11787 model online success
[2020-12-04 22:41:32] _internal.py[line:113] INFO 11787 127.0.0.1 - - [04/Dec/2020 22:41:32] "[37mPOST /online HTTP/1.1[0m" 200 -
[2020-12-04 22:41:36] MyServer.py[line:62] INFO 11787 get data: uuid: dadasdsadas;input: image:1 
[2020-12-04 22:42:10] _internal.py[line:113] INFO 12176  * Running on http://127.0.0.1:5000/ (Press CTRL+C to quit)
[2020-12-04 22:42:11] CaffeOpencvApp.py[line:91] INFO 12373 infer process start succeed
[2020-12-04 22:42:23] MyServer.py[line:34] INFO 12176 get data message, the data keys: dict_keys(['input', 'uuid', 'loadmodel', 'image_1'])
[2020-12-04 22:42:23] CaffeOpencvApp.py[line:95] INFO 12373 load modelfile: ('modelweight/MobileNetSSD_deploy.prototxt', 'modelweight/MobileNetSSD_deploy.caffemodel')
[2020-12-04 22:42:23] CaffeOpencvApp.py[line:101] INFO 12373 model has load('modelweight/MobileNetSSD_deploy.prototxt', 'modelweight/MobileNetSSD_deploy.caffemodel')
[2020-12-04 22:42:24] MyServer.py[line:39] INFO 12176 model online success
[2020-12-04 22:42:24] _internal.py[line:113] INFO 12176 127.0.0.1 - - [04/Dec/2020 22:42:24] "[37mPOST /online HTTP/1.1[0m" 200 -
[2020-12-04 22:42:30] MyServer.py[line:62] INFO 12176 get data: uuid: dadasdsadas;input: image:1 
[2020-12-04 22:48:07] _internal.py[line:113] INFO 12705  * Running on http://127.0.0.1:5000/ (Press CTRL+C to quit)
[2020-12-04 22:48:08] CaffeOpencvApp.py[line:91] INFO 12902 infer process start succeed
[2020-12-04 22:51:59] MyServer.py[line:34] INFO 12705 get data message, the data keys: dict_keys(['input', 'uuid', 'loadmodel', 'image_1'])
[2020-12-04 22:51:59] CaffeOpencvApp.py[line:95] INFO 12902 load modelfile: ('modelweight/MobileNetSSD_deploy.prototxt', 'modelweight/MobileNetSSD_deploy.caffemodel')
[2020-12-04 22:51:59] CaffeOpencvApp.py[line:101] INFO 12902 model has load('modelweight/MobileNetSSD_deploy.prototxt', 'modelweight/MobileNetSSD_deploy.caffemodel')
[2020-12-04 22:52:00] MyServer.py[line:39] INFO 12705 model online success
[2020-12-04 22:52:00] _internal.py[line:113] INFO 12705 127.0.0.1 - - [04/Dec/2020 22:52:00] "[37mPOST /online HTTP/1.1[0m" 200 -
[2020-12-04 22:52:03] MyServer.py[line:62] INFO 12705 get data: uuid: dadasdsadas;input: image:1 
[2020-12-04 22:52:09] app.py[line:1892] ERROR 12705 Exception on /postdata [POST]
Traceback (most recent call last):
  File "/root/anaconda3/envs/py3/lib/python3.6/site-packages/flask/app.py", line 2447, in wsgi_app
    response = self.full_dispatch_request()
  File "/root/anaconda3/envs/py3/lib/python3.6/site-packages/flask/app.py", line 1952, in full_dispatch_request
    rv = self.handle_user_exception(e)
  File "/root/anaconda3/envs/py3/lib/python3.6/site-packages/flask/app.py", line 1821, in handle_user_exception
    reraise(exc_type, exc_value, tb)
  File "/root/anaconda3/envs/py3/lib/python3.6/site-packages/flask/_compat.py", line 39, in reraise
    raise value
  File "/root/anaconda3/envs/py3/lib/python3.6/site-packages/flask/app.py", line 1950, in full_dispatch_request
    rv = self.dispatch_request()
  File "/root/anaconda3/envs/py3/lib/python3.6/site-packages/flask/app.py", line 1936, in dispatch_request
    return self.view_functions[rule.endpoint](**req.view_args)
  File "/root/MyApp/MyServer.py", line 80, in postdata
    return json.loads(processdata)
  File "/root/anaconda3/envs/py3/lib/python3.6/json/__init__.py", line 348, in loads
    'not {!r}'.format(s.__class__.__name__))
TypeError: the JSON object must be str, bytes or bytearray, not 'dict'
[2020-12-04 22:52:09] _internal.py[line:113] INFO 12705 127.0.0.1 - - [04/Dec/2020 22:52:09] "[35m[1mPOST /postdata HTTP/1.1[0m" 500 -
[2020-12-04 22:53:02] MyServer.py[line:62] INFO 12705 get data: uuid: dadasdsadas;input: image:1 
[2020-12-04 22:53:09] app.py[line:1892] ERROR 12705 Exception on /postdata [POST]
Traceback (most recent call last):
  File "/root/anaconda3/envs/py3/lib/python3.6/site-packages/flask/app.py", line 2447, in wsgi_app
    response = self.full_dispatch_request()
  File "/root/anaconda3/envs/py3/lib/python3.6/site-packages/flask/app.py", line 1952, in full_dispatch_request
    rv = self.handle_user_exception(e)
  File "/root/anaconda3/envs/py3/lib/python3.6/site-packages/flask/app.py", line 1821, in handle_user_exception
    reraise(exc_type, exc_value, tb)
  File "/root/anaconda3/envs/py3/lib/python3.6/site-packages/flask/_compat.py", line 39, in reraise
    raise value
  File "/root/anaconda3/envs/py3/lib/python3.6/site-packages/flask/app.py", line 1950, in full_dispatch_request
    rv = self.dispatch_request()
  File "/root/anaconda3/envs/py3/lib/python3.6/site-packages/flask/app.py", line 1936, in dispatch_request
    return self.view_functions[rule.endpoint](**req.view_args)
  File "/root/MyApp/MyServer.py", line 80, in postdata
    return json.loads(processdata)
  File "/root/anaconda3/envs/py3/lib/python3.6/json/__init__.py", line 348, in loads
    'not {!r}'.format(s.__class__.__name__))
TypeError: the JSON object must be str, bytes or bytearray, not 'dict'
[2020-12-04 22:53:09] _internal.py[line:113] INFO 12705 127.0.0.1 - - [04/Dec/2020 22:53:09] "[35m[1mPOST /postdata HTTP/1.1[0m" 500 -
[2020-12-04 22:54:01] _internal.py[line:113] INFO 13353  * Running on http://127.0.0.1:5000/ (Press CTRL+C to quit)
[2020-12-04 22:54:02] CaffeOpencvApp.py[line:91] INFO 13551 infer process start succeed
[2020-12-04 22:54:23] MyServer.py[line:34] INFO 13353 get data message, the data keys: dict_keys(['input', 'uuid', 'loadmodel', 'image_1'])
[2020-12-04 22:54:23] CaffeOpencvApp.py[line:95] INFO 13551 load modelfile: ('modelweight/MobileNetSSD_deploy.prototxt', 'modelweight/MobileNetSSD_deploy.caffemodel')
[2020-12-04 22:54:23] CaffeOpencvApp.py[line:101] INFO 13551 model has load('modelweight/MobileNetSSD_deploy.prototxt', 'modelweight/MobileNetSSD_deploy.caffemodel')
[2020-12-04 22:54:24] MyServer.py[line:39] INFO 13353 model online success
[2020-12-04 22:54:24] _internal.py[line:113] INFO 13353 127.0.0.1 - - [04/Dec/2020 22:54:24] "[37mPOST /online HTTP/1.1[0m" 200 -
[2020-12-04 23:18:14] MyServer.py[line:62] INFO 13353 get data: uuid: dadasdsadas;input: image:1 
[2020-12-04 23:18:21] _internal.py[line:113] INFO 13353 127.0.0.1 - - [04/Dec/2020 23:18:21] "[37mPOST /postdata HTTP/1.1[0m" 200 -
